<?xml version="1.0"?>
<robot xmlns:xacro="http://www.ros.org/wiki/xacro" name="robo_4_rodas">

  <!-- ============================================================
       Robô skid-steer 4 rodas (2 placas de hoverboard, ponte MEGA).
       Dimensões medidas no chassi atual (2026-05-11):
         carcaça externa : 50 × 50 × 26 cm
         estrutura interna: 37 × 35 × 16 cm (alumínio)
         roda hoverboard : raio 8,5 cm  largura 6 cm
         bitola (esq-dir): 50 cm
         entre-eixos     : 37 cm
       ============================================================ -->

  <xacro:property name="wheel_radius"     value="0.085"/>
  <xacro:property name="wheel_width"      value="0.06"/>
  <xacro:property name="track_width"      value="0.50"/>   <!-- bitola: distância entre centros L-R -->
  <xacro:property name="wheelbase"        value="0.37"/>   <!-- entre-eixos: distância entre eixos F-R -->

  <xacro:property name="body_length"      value="0.50"/>
  <xacro:property name="body_width"       value="0.50"/>
  <xacro:property name="body_height"      value="0.26"/>

  <!-- LiDAR no topo, ligeiramente à frente -->
  <xacro:property name="lidar_x"          value="0.10"/>
  <xacro:property name="lidar_z"          value="0.12"/>

  <!-- IMU (BNO055) e PMW3901 (optical flow) — montados no centro do chassi -->
  <xacro:property name="imu_z"            value="0.02"/>
  <xacro:property name="flow_z"           value="-0.03"/>

  <!-- ======= base_footprint ======= -->
  <link name="base_footprint"/>

  <joint name="base_footprint_joint" type="fixed">
    <parent link="base_footprint"/>
    <child link="base_link"/>
    <origin xyz="0 0 ${wheel_radius}" rpy="0 0 0"/>
  </joint>

  <!-- ======= base_link ======= -->
  <link name="base_link">
    <visual>
      <geometry>
        <box size="${body_length} ${body_width} ${body_height}"/>
      </geometry>
      <material name="grey">
        <color rgba="0.5 0.5 0.5 1.0"/>
      </material>
    </visual>
    <collision>
      <geometry>
        <box size="${body_length} ${body_width} ${body_height}"/>
      </geometry>
    </collision>
    <inertial>
      <mass value="15.46"/>
      <inertia ixx="0.5" ixy="0" ixz="0" iyy="0.5" iyz="0" izz="0.5"/>
    </inertial>
  </link>

  <!-- ======= Macro de roda ======= -->
  <xacro:macro name="wheel" params="name x y">
    <joint name="${name}_joint" type="continuous">
      <parent link="base_link"/>
      <child link="${name}"/>
      <origin xyz="${x} ${y} ${-body_height/2}" rpy="${-pi/2} 0 0"/>
      <axis xyz="0 0 1"/>
    </joint>
    <link name="${name}">
      <visual>
        <geometry>
          <cylinder radius="${wheel_radius}" length="${wheel_width}"/>
        </geometry>
        <material name="black">
          <color rgba="0.1 0.1 0.1 1.0"/>
        </material>
      </visual>
      <collision>
        <geometry>
          <cylinder radius="${wheel_radius}" length="${wheel_width}"/>
        </geometry>
      </collision>
      <inertial>
        <mass value="1.5"/>
        <inertia ixx="0.005" ixy="0" ixz="0" iyy="0.005" iyz="0" izz="0.009"/>
      </inertial>
    </link>
  </xacro:macro>

  <xacro:wheel name="front_left_wheel"  x="${ wheelbase/2}" y="${ track_width/2}"/>
  <xacro:wheel name="front_right_wheel" x="${ wheelbase/2}" y="${-track_width/2}"/>
  <xacro:wheel name="rear_left_wheel"   x="${-wheelbase/2}" y="${ track_width/2}"/>
  <xacro:wheel name="rear_right_wheel"  x="${-wheelbase/2}" y="${-track_width/2}"/>

  <!-- ======= LiDAR (FHL-LD20) ======= -->
  <joint name="laser_joint" type="fixed">
    <parent link="base_link"/>
    <child link="base_laser"/>
    <origin xyz="${lidar_x} 0 ${body_height/2 + lidar_z}" rpy="0 0 0"/>
  </joint>
  <link name="base_laser">
    <visual>
      <geometry>
        <cylinder radius="0.038" length="0.04"/>
      </geometry>
      <material name="blue">
        <color rgba="0.0 0.3 0.8 1.0"/>
      </material>
    </visual>
    <collision>
      <geometry>
        <cylinder radius="0.038" length="0.04"/>
      </geometry>
    </collision>
    <inertial>
      <mass value="0.1"/>
      <inertia ixx="0.0001" ixy="0" ixz="0" iyy="0.0001" iyz="0" izz="0.0001"/>
    </inertial>
  </link>

  <!-- ======= IMU (BNO055) ======= -->
  <joint name="imu_joint" type="fixed">
    <parent link="base_link"/>
    <child link="imu_link"/>
    <origin xyz="0 0 ${imu_z}" rpy="0 0 0"/>
  </joint>
  <link name="imu_link">
    <visual>
      <geometry>
        <box size="0.02 0.02 0.005"/>
      </geometry>
      <material name="red">
        <color rgba="0.8 0.1 0.1 1.0"/>
      </material>
    </visual>
    <inertial>
      <mass value="0.01"/>
      <inertia ixx="1e-5" ixy="0" ixz="0" iyy="1e-5" iyz="0" izz="1e-5"/>
    </inertial>
  </link>

  <!-- ======= Optical flow (PMW3901) — embaixo, olhando pro chão ======= -->
  <joint name="flow_joint" type="fixed">
    <parent link="base_link"/>
    <child link="flow_link"/>
    <origin xyz="0 0 ${-body_height/2 + flow_z}" rpy="0 ${pi} 0"/>
  </joint>
  <link name="flow_link">
    <visual>
      <geometry>
        <box size="0.02 0.02 0.005"/>
      </geometry>
      <material name="green">
        <color rgba="0.1 0.7 0.1 1.0"/>
      </material>
    </visual>
    <inertial>
      <mass value="0.01"/>
      <inertia ixx="1e-5" ixy="0" ixz="0" iyy="1e-5" iyz="0" izz="1e-5"/>
    </inertial>
  </link>

</robot>
