<?xml version="1.0"?>
<!--
  Robô skid-steer 4 RODAS simulado no Gazebo Harmonic.
  Medidas reais do chassi (2026-06-24, confirmadas pelo usuário):
    chassi 0.37 (frente-trás) x 0.35 (esq-dir) x 0.16 (altura)
    roda  raio 0.085 m (diâmetro 0.17), largura 0.06 m
    ponta-a-ponta das rodas = 0.50 m nas DUAS direções -> centros:
      track (esq-dir)   = 0.50 - largura 0.06   = 0.44  (wheel y = ±0.22)
      wheelbase (F-R)   = 0.50 - diâmetro 0.17   = 0.33  (wheel x = ±0.165)
    Mancal 3.5cm: TOPO preso na parte inferior do chassi, eixo da roda no MEIO
      dele. Logo o eixo fica 0.0175 abaixo do fundo do chassi -> o base_link
      sobe: z = raio(0.085) + mancal/2(0.0175) + body_height/2(0.08) = 0.1825.
    Eixo curto liga o mancal à roda (a roda fica POR FORA do mancal).
    LiDAR assentado no TOPO do chassi (sem mastro), z=0.10 acima do base_link.

  Skid-steer = DiffDrive c/ 2 left_joint + 2 right_joint. Giro no lugar por
  derrapagem: fdir1=(1 0 0) (direção de rolagem) + mu2 baixo (lateral escorrega).
  Nomes de links/juntas batem com sim_robot.urdf.xacro (robot_state_publisher).
  Tópicos ROS (bridge): /cmd_vel, /odom, /scan, /tf, /joint_states
-->
<sdf version="1.9">
  <model name="sim_robot">
    <!-- base_link (centro do chassi). z=0.1825 -> rodas tocam o chão
         (centro da roda em z=0.085=raio; mancal 3.5cm entre chassi e eixo). -->
    <pose>0 0 0.1825 0 0 0</pose>

    <!-- ====== base_link (chassi 0.37 x 0.35 x 0.16) ====== -->
    <link name="base_link">
      <inertial>
        <mass>15.46</mass>
        <!-- Caixa 0.37×0.35×0.16, m=15.46 -->
        <inertia>
          <ixx>0.19</ixx><iyy>0.21</iyy><izz>0.33</izz>
          <ixy>0</ixy><ixz>0</ixz><iyz>0</iyz>
        </inertia>
      </inertial>
      <visual name="body_visual">
        <geometry><box><size>0.37 0.35 0.16</size></box></geometry>
        <material>
          <ambient>0.5 0.5 0.5 1</ambient>
          <diffuse>0.55 0.55 0.55 1</diffuse>
          <specular>0.2 0.2 0.2 1</specular>
        </material>
      </visual>
      <collision name="body_collision">
        <geometry><box><size>0.37 0.35 0.16</size></box></geometry>
      </collision>
      <!-- Marca da frente (+x): faixa laranja no topo pra ver a orientação -->
      <visual name="front_marker">
        <pose>0.15 0 0.081 0 0 0</pose>
        <geometry><box><size>0.06 0.35 0.005</size></box></geometry>
        <material><ambient>0.9 0.45 0 1</ambient><diffuse>1 0.5 0 1</diffuse></material>
      </visual>

      <!-- ====== Mancais + eixos (visuais) ======
           Mancal: bloco 3.5cm com o TOPO no fundo do chassi (z_rel -0.08),
             centro em z_rel -0.0975 (= altura do eixo da roda), inboard (y=±0.16).
           Eixo: cilindro CURTO ao longo de Y, do mancal até a roda (y=±0.185).
           Roda fica POR FORA (y=±0.22). x = ±0.165 (mesmo das rodas). -->
      <!-- frente-esq -->
      <visual name="mancal_fl"><pose>0.165 0.16 -0.0975 0 0 0</pose>
        <geometry><box><size>0.04 0.04 0.035</size></box></geometry>
        <material><diffuse>0.2 0.2 0.2 1</diffuse></material></visual>
      <visual name="axle_fl"><pose>0.165 0.185 -0.0975 -1.5707 0 0</pose>
        <geometry><cylinder><radius>0.012</radius><length>0.05</length></cylinder></geometry>
        <material><diffuse>0.3 0.3 0.3 1</diffuse></material></visual>
      <!-- frente-dir -->
      <visual name="mancal_fr"><pose>0.165 -0.16 -0.0975 0 0 0</pose>
        <geometry><box><size>0.04 0.04 0.035</size></box></geometry>
        <material><diffuse>0.2 0.2 0.2 1</diffuse></material></visual>
      <visual name="axle_fr"><pose>0.165 -0.185 -0.0975 -1.5707 0 0</pose>
        <geometry><cylinder><radius>0.012</radius><length>0.05</length></cylinder></geometry>
        <material><diffuse>0.3 0.3 0.3 1</diffuse></material></visual>
      <!-- trás-esq -->
      <visual name="mancal_rl"><pose>-0.165 0.16 -0.0975 0 0 0</pose>
        <geometry><box><size>0.04 0.04 0.035</size></box></geometry>
        <material><diffuse>0.2 0.2 0.2 1</diffuse></material></visual>
      <visual name="axle_rl"><pose>-0.165 0.185 -0.0975 -1.5707 0 0</pose>
        <geometry><cylinder><radius>0.012</radius><length>0.05</length></cylinder></geometry>
        <material><diffuse>0.3 0.3 0.3 1</diffuse></material></visual>
      <!-- trás-dir -->
      <visual name="mancal_rr"><pose>-0.165 -0.16 -0.0975 0 0 0</pose>
        <geometry><box><size>0.04 0.04 0.035</size></box></geometry>
        <material><diffuse>0.2 0.2 0.2 1</diffuse></material></visual>
      <visual name="axle_rr"><pose>-0.165 -0.185 -0.0975 -1.5707 0 0</pose>
        <geometry><cylinder><radius>0.012</radius><length>0.05</length></cylinder></geometry>
        <material><diffuse>0.3 0.3 0.3 1</diffuse></material></visual>
    </link>

    <!-- ====== 4 rodas (skid-steer) ======
         z_rel = -0.0975 (centro em world z=0.085=raio) | x=±0.165 | y=±0.22
         rpy -1.5707 0 0 + axis 0 0 1 => roda gira em torno de Y (rola em +x)
         friction: fdir1=(1 0 0)=rolagem, mu alto (grip) / mu2 baixo (derrapa) -->
    <link name="front_left_wheel">
      <pose>0.165 0.22 -0.0975 -1.5707 0 0</pose>
      <inertial><mass>1.5</mass>
        <inertia><ixx>0.005</ixx><iyy>0.005</iyy><izz>0.009</izz><ixy>0</ixy><ixz>0</ixz><iyz>0</iyz></inertia>
      </inertial>
      <visual name="v"><geometry><cylinder><radius>0.085</radius><length>0.06</length></cylinder></geometry>
        <material><diffuse>0.1 0.1 0.1 1</diffuse></material></visual>
      <collision name="c"><geometry><cylinder><radius>0.085</radius><length>0.06</length></cylinder></geometry>
        <surface><friction><ode><mu>1.2</mu><mu2>0.1</mu2><fdir1>1 0 0</fdir1></ode></friction></surface></collision>
    </link>
    <joint name="front_left_wheel_joint" type="revolute">
      <parent>base_link</parent><child>front_left_wheel</child>
      <axis><xyz>0 0 1</xyz><limit><lower>-1e16</lower><upper>1e16</upper></limit></axis>
    </joint>

    <link name="front_right_wheel">
      <pose>0.165 -0.22 -0.0975 -1.5707 0 0</pose>
      <inertial><mass>1.5</mass>
        <inertia><ixx>0.005</ixx><iyy>0.005</iyy><izz>0.009</izz><ixy>0</ixy><ixz>0</ixz><iyz>0</iyz></inertia>
      </inertial>
      <visual name="v"><geometry><cylinder><radius>0.085</radius><length>0.06</length></cylinder></geometry>
        <material><diffuse>0.1 0.1 0.1 1</diffuse></material></visual>
      <collision name="c"><geometry><cylinder><radius>0.085</radius><length>0.06</length></cylinder></geometry>
        <surface><friction><ode><mu>1.2</mu><mu2>0.1</mu2><fdir1>1 0 0</fdir1></ode></friction></surface></collision>
    </link>
    <joint name="front_right_wheel_joint" type="revolute">
      <parent>base_link</parent><child>front_right_wheel</child>
      <axis><xyz>0 0 1</xyz><limit><lower>-1e16</lower><upper>1e16</upper></limit></axis>
    </joint>

    <link name="rear_left_wheel">
      <pose>-0.165 0.22 -0.0975 -1.5707 0 0</pose>
      <inertial><mass>1.5</mass>
        <inertia><ixx>0.005</ixx><iyy>0.005</iyy><izz>0.009</izz><ixy>0</ixy><ixz>0</ixz><iyz>0</iyz></inertia>
      </inertial>
      <visual name="v"><geometry><cylinder><radius>0.085</radius><length>0.06</length></cylinder></geometry>
        <material><diffuse>0.1 0.1 0.1 1</diffuse></material></visual>
      <collision name="c"><geometry><cylinder><radius>0.085</radius><length>0.06</length></cylinder></geometry>
        <surface><friction><ode><mu>1.2</mu><mu2>0.1</mu2><fdir1>1 0 0</fdir1></ode></friction></surface></collision>
    </link>
    <joint name="rear_left_wheel_joint" type="revolute">
      <parent>base_link</parent><child>rear_left_wheel</child>
      <axis><xyz>0 0 1</xyz><limit><lower>-1e16</lower><upper>1e16</upper></limit></axis>
    </joint>

    <link name="rear_right_wheel">
      <pose>-0.165 -0.22 -0.0975 -1.5707 0 0</pose>
      <inertial><mass>1.5</mass>
        <inertia><ixx>0.005</ixx><iyy>0.005</iyy><izz>0.009</izz><ixy>0</ixy><ixz>0</ixz><iyz>0</iyz></inertia>
      </inertial>
      <visual name="v"><geometry><cylinder><radius>0.085</radius><length>0.06</length></cylinder></geometry>
        <material><diffuse>0.1 0.1 0.1 1</diffuse></material></visual>
      <collision name="c"><geometry><cylinder><radius>0.085</radius><length>0.06</length></cylinder></geometry>
        <surface><friction><ode><mu>1.2</mu><mu2>0.1</mu2><fdir1>1 0 0</fdir1></ode></friction></surface></collision>
    </link>
    <joint name="rear_right_wheel_joint" type="revolute">
      <parent>base_link</parent><child>rear_right_wheel</child>
      <axis><xyz>0 0 1</xyz><limit><lower>-1e16</lower><upper>1e16</upper></limit></axis>
    </joint>

    <!-- ====== LiDAR 2D, assentado no TOPO do chassi ======
         z_rel = body_height/2 + meia-altura-do-lidar = 0.08 + 0.02 = 0.10 -->
    <link name="base_laser">
      <pose>0 0 0.10 0 0 0</pose>
      <inertial><mass>0.1</mass>
        <inertia><ixx>0.0001</ixx><iyy>0.0001</iyy><izz>0.0001</izz><ixy>0</ixy><ixz>0</ixz><iyz>0</iyz></inertia>
      </inertial>
      <visual name="lidar_visual">
        <geometry><cylinder><radius>0.038</radius><length>0.04</length></cylinder></geometry>
        <material><diffuse>0.0 0.3 0.8 1</diffuse></material>
      </visual>
      <sensor name="lidar" type="gpu_lidar">
        <update_rate>10</update_rate>
        <topic>scan</topic>
        <always_on>1</always_on>
        <visualize>true</visualize>
        <gz_frame_id>base_laser</gz_frame_id>
        <lidar>
          <scan>
            <horizontal>
              <samples>455</samples>
              <resolution>1</resolution>
              <min_angle>-3.14159</min_angle>
              <max_angle>3.14159</max_angle>
            </horizontal>
          </scan>
          <range>
            <min>0.10</min>
            <max>12.0</max>
            <resolution>0.01</resolution>
          </range>
        </lidar>
      </sensor>
    </link>
    <joint name="laser_joint" type="fixed">
      <parent>base_link</parent>
      <child>base_laser</child>
    </joint>

    <!-- ====== Plugins ====== -->
    <!-- Skid-steer: 2 juntas de cada lado. wheel_separation = track (centros) = 0.44 -->
    <plugin filename="gz-sim-diff-drive-system" name="gz::sim::systems::DiffDrive">
      <left_joint>front_left_wheel_joint</left_joint>
      <left_joint>rear_left_wheel_joint</left_joint>
      <right_joint>front_right_wheel_joint</right_joint>
      <right_joint>rear_right_wheel_joint</right_joint>
      <wheel_separation>0.44</wheel_separation>
      <wheel_radius>0.085</wheel_radius>
      <odom_publish_frequency>30</odom_publish_frequency>
      <topic>cmd_vel</topic>
      <odom_topic>odom</odom_topic>
      <frame_id>odom</frame_id>
      <child_frame_id>base_link</child_frame_id>
      <tf_topic>/tf</tf_topic>
      <max_linear_acceleration>1.5</max_linear_acceleration>
      <max_angular_acceleration>3.0</max_angular_acceleration>
    </plugin>

    <plugin filename="gz-sim-joint-state-publisher-system"
            name="gz::sim::systems::JointStatePublisher">
      <topic>joint_states</topic>
      <joint_name>front_left_wheel_joint</joint_name>
      <joint_name>front_right_wheel_joint</joint_name>
      <joint_name>rear_left_wheel_joint</joint_name>
      <joint_name>rear_right_wheel_joint</joint_name>
    </plugin>

    <plugin filename="gz-sim-pose-publisher-system"
            name="gz::sim::systems::PosePublisher">
      <publish_link_pose>true</publish_link_pose>
      <publish_sensor_pose>true</publish_sensor_pose>
      <publish_collision_pose>false</publish_collision_pose>
      <publish_visual_pose>false</publish_visual_pose>
      <publish_nested_model_pose>false</publish_nested_model_pose>
      <use_pose_vector_msg>true</use_pose_vector_msg>
      <static_publisher>false</static_publisher>
      <static_update_frequency>1</static_update_frequency>
    </plugin>
  </model>
</sdf>
